Workbook

Sheet RICE_Insured Farms_with PPI Pol
A1: No. | B1: Program Type | C1: Province | D1: Municipality | E1: Barangay | F1: Policy No. | G1: Effectivity Date | H1: Expiry Date | I1: Surname | J1: Firstname | K1: Middlename | L1: AreaInsured | M1: AmountofCover | N1: Stage No. | O1: FarmersID | P1: RSBSA No. | Q1: Farm ID | R1: Georef ID | S1: RiskExposureAmount | T1: Stage | U1: EstimatedDamage | V1: Days from Planting to Typhoon Occurance | W1: Adjuster's Stage of Crop Calculation
A2: 1 | B2: RSBSA | C2: Agusan del Norte | D2: BUTUAN CITY | E2: LEMON | F2: 1761007 | G2: 46019 | H2: 46139 | I2: AGUDONG | J2: ALLAN | K2: ALUAG | L2: 1.11 | M2: 27750 | N2: 2 | O2: 127451 | P2: 16-02-02-052-000075 | Q2: 390975 | S2: 19425 | T2: 2 - Mx. Tl. Stg. (LATE VEGETATIVE) | U2: 19425 | V2: =(DATE(2026,2,3)-'RICE_Insured Farms_with PPI Pol'!$G2)+IF('RICE_Insured Farms_with PPI Pol'!$H2<>'RICE_Insured Farms_with PPI Pol'!$G2,18,0) -> 55 | W2: {=IFS(V2>120, "Harvested", V2>=113, "Yellow Ripening", V2>=101, "Dough Stage", V2>=93, "Milking Stage", V2>=86, "Flowering", V2>=56, "Panicle Initiation/Booting", V2<56, "Vegetative/Tillering")} -> Vegetative/Tillering
A3: 2 | B3: RSBSA | C3: Agusan del Norte | D3: BUTUAN CITY | E3: ANTONGALON | F3: 1760478 | G3: 46014 | H3: 46114 | I3: AJOS | J3: EDNA | K3: COMPESINO | L3: 0.3564 | M3: 8910 | N3: 3 | O3: 313897 | P3: 16-02-02-009-000004 | Q3: 572646 | S3: 7128 | T3: 3 - P. I. Stg. (REPRODUCTIVE) | U3: 7128 | V3: =(DATE(2026,2,3)-'RICE_Insured Farms_with PPI Pol'!$G3)+IF('RICE_Insured Farms_with PPI Pol'!$H3<>'RICE_Insured Farms_with PPI Pol'!$G3,18,0) -> 60 | W3: {=IFS(V3>120, "Harvested", V3>=113, "Yellow Ripening", V3>=101, "Dough Stage", V3>=93, "Milking Stage", V3>=86, "Flowering", V3>=56, "Panicle Initiation/Booting", V3<56, "Vegetative/Tillering")} -> Panicle Initiation/Booting
A4: 3 | B4: RSBSA | C4: Agusan del Norte | D4: BUTUAN CITY | E4: ANTONGALON | F4: 1760476 | G4: 46014 | H4: 46112 | I4: ALAGO | J4: HENRY | K4: EFONDOL | L4: 1.5 | M4: 37500 | N4: 3 | O4: 294980 | P4: 16-02-02-009-000005 | Q4: 603915 | S4: 30000 | T4: 3 - P. I. Stg. (REPRODUCTIVE) | U4: 30000 | V4: =(DATE(2026,2,3)-'RICE_Insured Farms_with PPI Pol'!$G4)+IF('RICE_Insured Farms_with PPI Pol'!$H4<>'RICE_Insured Farms_with PPI Pol'!$G4,18,0) -> 60 | W4: {=IFS(V4>120, "Harvested", V4>=113, "Yellow Ripening", V4>=101, "Dough Stage", V4>=93, "Milking Stage", V4>=86, "Flowering", V4>=56, "Panicle Initiation/Booting", V4<56, "Vegetative/Tillering")} -> Panicle Initiation/Booting
A5: 4 | B5: RSBSA | C5: Agusan del Norte | D5: BUTUAN CITY | E5: LEMON | F5: 1760459 | G5: 46015 | H5: 46112 | I5: AVENIDO | J5: DANILO | K5: BAAY | L5: 1 | M5: 25000 | N5: 3 | O5: 369934 | P5: 16-02-02-052-000062 | Q5: 727077 | S5: 20000 | T5: 3 - P. I. Stg. (REPRODUCTIVE) | U5: 20000 | V5: =(DATE(2026,2,3)-'RICE_Insured Farms_with PPI Pol'!$G5)+IF('RICE_Insured Farms_with PPI Pol'!$H5<>'RICE_Insured Farms_with PPI Pol'!$G5,18,0) -> 59 | W5: {=IFS(V5>120, "Harvested", V5>=113, "Yellow Ripening", V5>=101, "Dough Stage", V5>=93, "Milking Stage", V5>=86, "Flowering", V5>=56, "Panicle Initiation/Booting", V5<56, "Vegetative/Tillering")} -> Panicle Initiation/Booting
A6: 5 | B6: RSBSA | C6: Agusan del Norte | D6: BUTUAN CITY | E6: LEMON | F6: 1760459 | G6: 46014 | H6: 46113 | I6: AYUBAN | J6: MARCELINA | K6: CAJUTOL | L6: 1 | M6: 25000 | N6: 3 | O6: 85802 | P6: 16-02-02-052-000102 | Q6: 476759 | S6: 20000 | T6: 3 - P. I. Stg. (REPRODUCTIVE) | U6: 20000 | V6: =(DATE(2026,2,3)-'RICE_Insured Farms_with PPI Pol'!$G6)+IF('RICE_Insured Farms_with PPI Pol'!$H6<>'RICE_Insured Farms_with PPI Pol'!$G6,18,0) -> 60 | W6: {=IFS(V6>120, "Harvested", V6>=113, "Yellow Ripening", V6>=101, "Dough Stage", V6>=93, "Milking Stage", V6>=86, "Flowering", V6>=56, "Panicle Initiation/Booting", V6<56, "Vegetative/Tillering")} -> Panicle Initiation/Booting
A7: 1418 | B7: RSBSA | C7: Misamis Oriental | D7: ALUBIJID | E7: LOURDES | F7: 1741852 | G7: 46011 | H7: 46106 | I7: TAMBIS | J7: JUANITO JR | K7: ROILO | L7: 1.227 | M7: 30675 | N7: 4 | O7: 34852 | Q7: 1279410 | S7: 24540 | T7: 4 - Booting Stg. (REPRODUCTIVE) | U7: 24540 | V7: =(DATE(2026,2,3)-'RICE_Insured Farms_with PPI Pol'!$G7)+IF('RICE_Insured Farms_with PPI Pol'!$H7<>'RICE_Insured Farms_with PPI Pol'!$G7,18,0) -> 63 | W7: {=IFS(V7>120, "Harvested", V7>=113, "Yellow Ripening", V7>=101, "Dough Stage", V7>=93, "Milking Stage", V7>=86, "Flowering", V7>=56, "Panicle Initiation/Booting", V7<56, "Vegetative/Tillering")} -> Panicle Initiation/Booting
A8: 7 | B8: RSBSA | C8: Agusan del Norte | D8: BUTUAN CITY | E8: BASAG | F8: 1761005 | G8: 46031 | H8: 46151 | I8: BAGO | J8: RICHIELE | K8: GENODEPANON | L8: 0.9303 | M8: 23257.5 | N8: 1 | O8: 362064 | P8: 16-02-02-019-000371 | Q8: 708065 | S8: 13954.5 | T8: 1 - Mn. Tl. Stg. (EARLY VEGETATIVE) | U8: 13954.5 | V8: =(DATE(2026,2,3)-'RICE_Insured Farms_with PPI Pol'!$G8)+IF('RICE_Insured Farms_with PPI Pol'!$H8<>'RICE_Insured Farms_with PPI Pol'!$G8,18,0) -> 43 | W8: {=IFS(V8>120, "Harvested", V8>=113, "Yellow Ripening", V8>=101, "Dough Stage", V8>=93, "Milking Stage", V8>=86, "Flowering", V8>=56, "Panicle Initiation/Booting", V8<56, "Vegetative/Tillering")} -> Vegetative/Tillering
A9: 8 | B9: RSBSA | C9: Agusan del Norte | D9: BUTUAN CITY | E9: AUPAGAN | F9: 1761018 | G9: 46031 | H9: 46126 | I9: BASANAL | J9: SOL | K9: DEL MUNDO | L9: 1.2146 | M9: 30365 | N9: 3 | O9: 325633 | P9: 16-02-02-010-000015 | Q9: 607439 | S9: 24292 | T9: 3 - P. I. Stg. (REPRODUCTIVE) | U9: 24292 | V9: =(DATE(2026,2,3)-'RICE_Insured Farms_with PPI Pol'!$G9)+IF('RICE_Insured Farms_with PPI Pol'!$H9<>'RICE_Insured Farms_with PPI Pol'!$G9,18,0) -> 43 | W9: {=IFS(V9>120, "Harvested", V9>=113, "Yellow Ripening", V9>=101, "Dough Stage", V9>=93, "Milking Stage", V9>=86, "Flowering", V9>=56, "Panicle Initiation/Booting", V9<56, "Vegetative/Tillering")} -> Vegetative/Tillering
A10: 115 | B10: RSBSA | C10: Surigao del Norte | D10: BACUAG | E10: DUGSANGON | F10: 1739640 | G10: 46006 | H10: 46108 | I10: GALAGAR | J10: NICOLAS | K10: ILIGAN | L10: 1.0114 | M10: 25285 | N10: 4 | O10: 338094 | P10: 16-67-02-004-000248 | Q10: 1022382 | S10: 20228 | T10: 4 - Booting Stg. (REPRODUCTIVE) | U10: 20228 | V10: =(DATE(2026,2,3)-'RICE_Insured Farms_with PPI Pol'!$G10)+IF('RICE_Insured Farms_with PPI Pol'!$H10<>'RICE_Insured Farms_with PPI Pol'!$G10,18,0) -> 68 | W10: {=IFS(V10>120, "Harvested", V10>=113, "Yellow Ripening", V10>=101, "Dough Stage", V10>=93, "Milking Stage", V10>=86, "Flowering", V10>=56, "Panicle Initiation/Booting", V10<56, "Vegetative/Tillering")} -> Panicle Initiation/Booting
A11: 10 | B11: RSBSA | C11: Agusan del Norte | D11: BUTUAN CITY | E11: ANTONGALON | F11: 1760479 | G11: 46011 | H11: 46112 | I11: BERDIN | J11: RAY | K11: HINGPIT | L11: 0.9121 | M11: 22802.5 | N11: 3 | O11: 192791 | Q11: 512629 | S11: 18242 | T11: 3 - P. I. Stg. (REPRODUCTIVE) | U11: 18242 | V11: =(DATE(2026,2,3)-'RICE_Insured Farms_with PPI Pol'!$G11)+IF('RICE_Insured Farms_with PPI Pol'!$H11<>'RICE_Insured Farms_with PPI Pol'!$G11,18,0) -> 63 | W11: {=IFS(V11>120, "Harvested", V11>=113, "Yellow Ripening", V11>=101, "Dough Stage", V11>=93, "Milking Stage", V11>=86, "Flowering", V11>=56, "Panicle Initiation/Booting", V11<56, "Vegetative/Tillering")} -> Panicle Initiation/Booting
A12: 11 | B12: RSBSA | C12: Agusan del Norte | D12: BUTUAN CITY | E12: ANTONGALON | F12: 1760476 | G12: 46011 | H12: 46112 | I12: BORCIS | J12: EUGENE | K12: LANGANLANGAN | L12: 1.9891 | M12: 49727.5 | N12: 3 | O12: 294979 | P12: 16-02-02-009-000008 | Q12: 603919 | S12: 39782 | T12: 3 - P. I. Stg. (REPRODUCTIVE) | U12: 39782 | V12: =(DATE(2026,2,3)-'RICE_Insured Farms_with PPI Pol'!$G12)+IF('RICE_Insured Farms_with PPI Pol'!$H12<>'RICE_Insured Farms_with PPI Pol'!$G12,18,0) -> 63 | W12: {=IFS(V12>120, "Harvested", V12>=113, "Yellow Ripening", V12>=101, "Dough Stage", V12>=93, "Milking Stage", V12>=86, "Flowering", V12>=56, "Panicle Initiation/Booting", V12<56, "Vegetative/Tillering")} -> Panicle Initiation/Booting
A13: 12 | B13: RSBSA | C13: Agusan del Norte | D13: BUTUAN CITY | E13: ANTONGALON | F13: 1760479 | G13: 46016 | H13: 46126 | I13: BORNALES | J13: ARC WILLIAM | K13: HERIA | L13: 0.989 | M13: 24725 | N13: 3 | O13: 313904 | Q13: 572661 | S13: 19780 | T13: 3 - P. I. Stg. (REPRODUCTIVE) | U13: 19780 | V13: =(DATE(2026,2,3)-'RICE_Insured Farms_with PPI Pol'!$G13)+IF('RICE_Insured Farms_with PPI Pol'!$H13<>'RICE_Insured Farms_with PPI Pol'!$G13,18,0) -> 58 | W13: {=IFS(V13>120, "Harvested", V13>=113, "Yellow Ripening", V13>=101, "Dough Stage", V13>=93, "Milking Stage", V13>=86, "Flowering", V13>=56, "Panicle Initiation/Booting", V13<56, "Vegetative/Tillering")} -> Panicle Initiation/Booting
A14: 13 | B14: RSBSA | C14: Agusan del Norte | D14: BUTUAN CITY | E14: ANTONGALON | F14: 1760479 | G14: 46011 | H14: 46131 | I14: BORNALES | J14: ARTUS | K14: MONEBIT | L14: 2.6704 | M14: 66760 | N14: 2 | O14: 192790 | P14: 16-02-02-009-000032 | Q14: 603986 | S14: 46732 | T14: 2 - Mx. Tl. Stg. (LATE VEGETATIVE) | U14: 46732 | V14: =(DATE(2026,2,3)-'RICE_Insured Farms_with PPI Pol'!$G14)+IF('RICE_Insured Farms_with PPI Pol'!$H14<>'RICE_Insured Farms_with PPI Pol'!$G14,18,0) -> 63 | W14: {=IFS(V14>120, "Harvested", V14>=113, "Yellow Ripening", V14>=101, "Dough Stage", V14>=93, "Milking Stage", V14>=86, "Flowering", V14>=56, "Panicle Initiation/Booting", V14<56, "Vegetative/Tillering")} -> Panicle Initiation/Booting
A15: 14 | B15: RSBSA | C15: Agusan del Norte | D15: BUTUAN CITY | E15: ANTONGALON | F15: 1760479 | G15: 46012 | H15: 46113 | I15: CABARSE | J15: FEDERICO | K15: PALIMA | L15: 2.6669 | M15: 66672.5 | N15: 3 | O15: 192461 | Q15: 604013 | S15: 53338 | T15: 3 - P. I. Stg. (REPRODUCTIVE) | U15: 53338 | V15: =(DATE(2026,2,3)-'RICE_Insured Farms_with PPI Pol'!$G15)+IF('RICE_Insured Farms_with PPI Pol'!$H15<>'RICE_Insured Farms_with PPI Pol'!$G15,18,0) -> 62 | W15: {=IFS(V15>120, "Harvested", V15>=113, "Yellow Ripening", V15>=101, "Dough Stage", V15>=93, "Milking Stage", V15>=86, "Flowering", V15>=56, "Panicle Initiation/Booting", V15<56, "Vegetative/Tillering")} -> Panicle Initiation/Booting
A16: 15 | B16: RSBSA | C16: Agusan del Norte | D16: BUTUAN CITY | E16: ANTONGALON | F16: 1760479 | G16: 46011 | H16: 46112 | I16: CABARSE | J16: GASPAR | K16: TAGRA | L16: 1.4525 | M16: 36312.5 | N16: 3 | O16: 122911 | P16: 16-02-02-009-000010 | Q16: 604215 | S16: 29050 | T16: 3 - P. I. Stg. (REPRODUCTIVE) | U16: 29050 | V16: =(DATE(2026,2,3)-'RICE_Insured Farms_with PPI Pol'!$G16)+IF('RICE_Insured Farms_with PPI Pol'!$H16<>'RICE_Insured Farms_with PPI Pol'!$G16,18,0) -> 63 | W16: {=IFS(V16>120, "Harvested", V16>=113, "Yellow Ripening", V16>=101, "Dough Stage", V16>=93, "Milking Stage", V16>=86, "Flowering", V16>=56, "Panicle Initiation/Booting", V16<56, "Vegetative/Tillering")} -> Panicle Initiation/Booting
A17: 116 | B17: RSBSA | C17: Surigao del Norte | D17: BACUAG | E17: DUGSANGON | F17: 1739640 | G17: 46007 | H17: 46109 | I17: GALAGAR | J17: ROSELINDO SR. | K17: ILIGAN | L17: 1 | M17: 25000 | N17: 4 | O17: 187790 | Q17: 1029398 | S17: 20000 | T17: 4 - Booting Stg. (REPRODUCTIVE) | U17: 20000 | V17: =(DATE(2026,2,3)-'RICE_Insured Farms_with PPI Pol'!$G17)+IF('RICE_Insured Farms_with PPI Pol'!$H17<>'RICE_Insured Farms_with PPI Pol'!$G17,18,0) -> 67 | W17: {=IFS(V17>120, "Harvested", V17>=113, "Yellow Ripening", V17>=101, "Dough Stage", V17>=93, "Milking Stage", V17>=86, "Flowering", V17>=56, "Panicle Initiation/Booting", V17<56, "Vegetative/Tillering")} -> Panicle Initiation/Booting
A18: 17 | B18: RSBSA | C18: Agusan del Norte | D18: BUTUAN CITY | E18: ANTONGALON | F18: 1760476 | G18: 46014 | H18: 46112 | I18: CAGA | J18: LINO | K18: MAPUTI | L18: 0.8935 | M18: 22337.5 | N18: 3 | O18: 233371 | P18: 16-02-02-009-000012 | Q18: 512620 | S18: 17870 | T18: 3 - P. I. Stg. (REPRODUCTIVE) | U18: 17870 | V18: =(DATE(2026,2,3)-'RICE_Insured Farms_with PPI Pol'!$G18)+IF('RICE_Insured Farms_with PPI Pol'!$H18<>'RICE_Insured Farms_with PPI Pol'!$G18,18,0) -> 60 | W18: {=IFS(V18>120, "Harvested", V18>=113, "Yellow Ripening", V18>=101, "Dough Stage", V18>=93, "Milking Stage", V18>=86, "Flowering", V18>=56, "Panicle Initiation/Booting", V18<56, "Vegetative/Tillering")} -> Panicle Initiation/Booting
A19: 18 | B19: RSBSA | C19: Agusan del Norte | D19: BUTUAN CITY | E19: ANTONGALON | F19: 1760476 | G19: 46011 | H19: 46121 | I19: CARIN | J19: CARMELITA | K19: CESNEROS | L19: 0.9068 | M19: 22670 | N19: 3 | O19: 324673 | Q19: 604248 | S19: 18136 | T19: 3 - P. I. Stg. (REPRODUCTIVE) | U19: 18136 | V19: =(DATE(2026,2,3)-'RICE_Insured Farms_with PPI Pol'!$G19)+IF('RICE_Insured Farms_with PPI Pol'!$H19<>'RICE_Insured Farms_with PPI Pol'!$G19,18,0) -> 63 | W19: {=IFS(V19>120, "Harvested", V19>=113, "Yellow Ripening", V19>=101, "Dough Stage", V19>=93, "Milking Stage", V19>=86, "Flowering", V19>=56, "Panicle Initiation/Booting", V19<56, "Vegetative/Tillering")} -> Panicle Initiation/Booting
A20: 19 | B20: RSBSA | C20: Agusan del Norte | D20: BUTUAN CITY | E20: ANTONGALON | F20: 1760476 | G20: 46014 | H20: 46124 | I20: CARIN | J20: MARGARITO | K20: CESNIROS | L20: 2 | M20: 50000 | N20: 3 | O20: 294859 | Q20: 603998 | S20: 40000 | T20: 3 - P. I. Stg. (REPRODUCTIVE) | U20: 40000 | V20: =(DATE(2026,2,3)-'RICE_Insured Farms_with PPI Pol'!$G20)+IF('RICE_Insured Farms_with PPI Pol'!$H20<>'RICE_Insured Farms_with PPI Pol'!$G20,18,0) -> 60 | W20: {=IFS(V20>120, "Harvested", V20>=113, "Yellow Ripening", V20>=101, "Dough Stage", V20>=93, "Milking Stage", V20>=86, "Flowering", V20>=56, "Panicle Initiation/Booting", V20<56, "Vegetative/Tillering")} -> Panicle Initiation/Booting
A21: 20 | B21: RSBSA | C21: Agusan del Norte | D21: BUTUAN CITY | E21: BASAG | F21: 1761032 | G21: 46037 | H21: 46157 | I21: CATAP | J21: LAURO | K21: ACEDO | L21: 0.6562 | M21: 16405 | N21: 1 | O21: 50132 | P21: 16-02-02-019-000433 | Q21: 402509 | S21: 9843 | T21: 1 - Mn. Tl. Stg. (EARLY VEGETATIVE) | U21: 9843 | V21: =(DATE(2026,2,3)-'RICE_Insured Farms_with PPI Pol'!$G21)+IF('RICE_Insured Farms_with PPI Pol'!$H21<>'RICE_Insured Farms_with PPI Pol'!$G21,18,0) -> 37 | W21: {=IFS(V21>120, "Harvested", V21>=113, "Yellow Ripening", V21>=101, "Dough Stage", V21>=93, "Milking Stage", V21>=86, "Flowering", V21>=56, "Panicle Initiation/Booting", V21<56, "Vegetative/Tillering")} -> Vegetative/Tillering
A22: 21 | B22: RSBSA | C22: Agusan del Norte | D22: BUTUAN CITY | E22: BASAG | F22: 1761032 | G22: 46027 | H22: 46147 | I22: CERNA | J22: DIVINA | K22: GALISA | L22: 1.0921 | M22: 27302.5 | N22: 1 | O22: 192095 | P22: 16-02-02-019-000385 | Q22: 613630 | S22: 16381.5 | T22: 1 - Mn. Tl. Stg. (EARLY VEGETATIVE) | U22: 16381.5 | V22: =(DATE(2026,2,3)-'RICE_Insured Farms_with PPI Pol'!$G22)+IF('RICE_Insured Farms_with PPI Pol'!$H22<>'RICE_Insured Farms_with PPI Pol'!$G22,18,0) -> 47 | W22: {=IFS(V22>120, "Harvested", V22>=113, "Yellow Ripening", V22>=101, "Dough Stage", V22>=93, "Milking Stage", V22>=86, "Flowering", V22>=56, "Panicle Initiation/Booting", V22<56, "Vegetative/Tillering")} -> Vegetative/Tillering
A23: 22 | B23: RSBSA | C23: Agusan del Norte | D23: BUTUAN CITY | E23: BOBON | F23: 1761028 | G23: 46021 | H23: 46116 | I23: COLIMA | J23: GEMMA | K23: OYAN | L23: 1.028 | M23: 25700 | N23: 3 | O23: 161074 | P23: 16-02-02-024-000022 | Q23: 723520 | S23: 20560 | T23: 3 - P. I. Stg. (REPRODUCTIVE) | U23: 20560 | V23: =(DATE(2026,2,3)-'RICE_Insured Farms_with PPI Pol'!$G23)+IF('RICE_Insured Farms_with PPI Pol'!$H23<>'RICE_Insured Farms_with PPI Pol'!$G23,18,0) -> 53 | W23: {=IFS(V23>120, "Harvested", V23>=113, "Yellow Ripening", V23>=101, "Dough Stage", V23>=93, "Milking Stage", V23>=86, "Flowering", V23>=56, "Panicle Initiation/Booting", V23<56, "Vegetative/Tillering")} -> Vegetative/Tillering
A24: 23 | B24: RSBSA | C24: Agusan del Norte | D24: BUTUAN CITY | E24: BOBON | F24: 1761028 | G24: 46020 | H24: 46116 | I24: COLIMA | J24: JAYROL | K24: TANIO | L24: 1.2284 | M24: 30710 | N24: 3 | O24: 123961 | P24: 16-02-02-024-000017 | Q24: 723548 | S24: 24568 | T24: 3 - P. I. Stg. (REPRODUCTIVE) | U24: 24568 | V24: =(DATE(2026,2,3)-'RICE_Insured Farms_with PPI Pol'!$G24)+IF('RICE_Insured Farms_with PPI Pol'!$H24<>'RICE_Insured Farms_with PPI Pol'!$G24,18,0) -> 54 | W24: {=IFS(V24>120, "Harvested", V24>=113, "Yellow Ripening", V24>=101, "Dough Stage", V24>=93, "Milking Stage", V24>=86, "Flowering", V24>=56, "Panicle Initiation/Booting", V24<56, "Vegetative/Tillering")} -> Vegetative/Tillering
A25: 24 | B25: RSBSA | C25: Agusan del Sur | D25: SAN FRANCISCO | E25: LAPINIGAN | F25: 1760507 | G25: 46021 | H25: 46141 | I25: COLON | J25: ESTRELLA | K25: CUIZON | L25: 1.4528 | M25: 36320 | N25: 2 | O25: 169004 | Q25: 703246 | S25: 25424 | T25: 2 - Mx. Tl. Stg. (LATE VEGETATIVE) | U25: 25424 | V25: =(DATE(2026,2,3)-'RICE_Insured Farms_with PPI Pol'!$G25)+IF('RICE_Insured Farms_with PPI Pol'!$H25<>'RICE_Insured Farms_with PPI Pol'!$G25,18,0) -> 53 | W25: {=IFS(V25>120, "Harvested", V25>=113, "Yellow Ripening", V25>=101, "Dough Stage", V25>=93, "Milking Stage", V25>=86, "Flowering", V25>=56, "Panicle Initiation/Booting", V25<56, "Vegetative/Tillering")} -> Vegetative/Tillering
A26: 25 | B26: RSBSA | C26: Agusan del Norte | D26: BUTUAN CITY | E26: ANTONGALON | F26: 1760482 | G26: 46011 | H26: 46131 | I26: CUARES | J26: BRILLO | K26: GALANIDA | L26: 1.197 | M26: 29925 | N26: 2 | O26: 192784 | P26: 16-02-02-009-000208 | Q26: 512631 | S26: 20947.5 | T26: 2 - Mx. Tl. Stg. (LATE VEGETATIVE) | U26: 20947.5 | V26: =(DATE(2026,2,3)-'RICE_Insured Farms_with PPI Pol'!$G26)+IF('RICE_Insured Farms_with PPI Pol'!$H26<>'RICE_Insured Farms_with PPI Pol'!$G26,18,0) -> 63 | W26: {=IFS(V26>120, "Harvested", V26>=113, "Yellow Ripening", V26>=101, "Dough Stage", V26>=93, "Milking Stage", V26>=86, "Flowering", V26>=56, "Panicle Initiation/Booting", V26<56, "Vegetative/Tillering")} -> Panicle Initiation/Booting
A27: 126 | B27: RSBSA | C27: Surigao del Norte | D27: BACUAG | E27: PAUTAO | F27: 1739640 | G27: 46001 | H27: 46103 | I27: IBARRA | J27: REVILYN | K27: UGAY | L27: 0.5 | M27: 12500 | N27: 4 | O27: 228437 | P27: 16-67-02-005-000188 | Q27: 1025316 | S27: 10000 | T27: 4 - Booting Stg. (REPRODUCTIVE) | U27: 10000 | V27: =(DATE(2026,2,3)-'RICE_Insured Farms_with PPI Pol'!$G27)+IF('RICE_Insured Farms_with PPI Pol'!$H27<>'RICE_Insured Farms_with PPI Pol'!$G27,18,0) -> 73 | W27: {=IFS(V27>120, "Harvested", V27>=113, "Yellow Ripening", V27>=101, "Dough Stage", V27>=93, "Milking Stage", V27>=86, "Flowering", V27>=56, "Panicle Initiation/Booting", V27<56, "Vegetative/Tillering")} -> Panicle Initiation/Booting
A28: 27 | B28: RSBSA | C28: Agusan del Norte | D28: BUTUAN CITY | E28: BASAG | F28: 1761031 | G28: 46020 | H28: 46140 | I28: DICDICAN | J28: EDNA | K28: MONDEJAR | L28: 0.6019 | M28: 15047.5 | N28: 2 | O28: 197919 | P28: 16-02-02-019-000105 | Q28: 723166 | S28: 10533.25 | T28: 2 - Mx. Tl. Stg. (LATE VEGETATIVE) | U28: 10533.25 | V28: =(DATE(2026,2,3)-'RICE_Insured Farms_with PPI Pol'!$G28)+IF('RICE_Insured Farms_with PPI Pol'!$H28<>'RICE_Insured Farms_with PPI Pol'!$G28,18,0) -> 54 | W28: {=IFS(V28>120, "Harvested", V28>=113, "Yellow Ripening", V28>=101, "Dough Stage", V28>=93, "Milking Stage", V28>=86, "Flowering", V28>=56, "Panicle Initiation/Booting", V28<56, "Vegetative/Tillering")} -> Vegetative/Tillering
A29: 28 | B29: RSBSA | C29: Agusan del Norte | D29: BUTUAN CITY | E29: BASAG | F29: 1761031 | G29: 46037 | H29: 46157 | I29: DICDICAN | J29: LORETO JR | K29: SUPANGAN | L29: 0.9956 | M29: 24890 | N29: 1 | O29: 113229 | Q29: 647403 | S29: 14934 | T29: 1 - Mn. Tl. Stg. (EARLY VEGETATIVE) | U29: 14934 | V29: =(DATE(2026,2,3)-'RICE_Insured Farms_with PPI Pol'!$G29)+IF('RICE_Insured Farms_with PPI Pol'!$H29<>'RICE_Insured Farms_with PPI Pol'!$G29,18,0) -> 37 | W29: {=IFS(V29>120, "Harvested", V29>=113, "Yellow Ripening", V29>=101, "Dough Stage", V29>=93, "Milking Stage", V29>=86, "Flowering", V29>=56, "Panicle Initiation/Booting", V29<56, "Vegetative/Tillering")} -> Vegetative/Tillering
A30: 29 | B30: RSBSA | C30: Agusan del Norte | D30: BUTUAN CITY | E30: ANTONGALON | F30: 1760478 | G30: 46012 | H30: 46113 | I30: DICDICAN | J30: TEOTIMO | K30: LINARES | L30: 1.384 | M30: 34600 | N30: 3 | O30: 233200 | P30: 16-02-02-009-000059 | Q30: 569796 | S30: 27680 | T30: 3 - P. I. Stg. (REPRODUCTIVE) | U30: 27680 | V30: =(DATE(2026,2,3)-'RICE_Insured Farms_with PPI Pol'!$G30)+IF('RICE_Insured Farms_with PPI Pol'!$H30<>'RICE_Insured Farms_with PPI Pol'!$G30,18,0) -> 62 | W30: {=IFS(V30>120, "Harvested", V30>=113, "Yellow Ripening", V30>=101, "Dough Stage", V30>=93, "Milking Stage", V30>=86, "Flowering", V30>=56, "Panicle Initiation/Booting", V30<56, "Vegetative/Tillering")} -> Panicle Initiation/Booting
A31: 30 | B31: RSBSA | C31: Agusan del Norte | D31: BUTUAN CITY | E31: TINIWISAN | F31: 1761019 | G31: 46021 | H31: 46116 | I31: DUNCANO | J31: VIRGILIO | K31: D | L31: 1.0165 | M31: 25412.5 | N31: 3 | O31: 367937 | Q31: 722333 | S31: 20330 | T31: 3 - P. I. Stg. (REPRODUCTIVE) | U31: 20330 | V31: =(DATE(2026,2,3)-'RICE_Insured Farms_with PPI Pol'!$G31)+IF('RICE_Insured Farms_with PPI Pol'!$H31<>'RICE_Insured Farms_with PPI Pol'!$G31,18,0) -> 53 | W31: {=IFS(V31>120, "Harvested", V31>=113, "Yellow Ripening", V31>=101, "Dough Stage", V31>=93, "Milking Stage", V31>=86, "Flowering", V31>=56, "Panicle Initiation/Booting", V31<56, "Vegetative/Tillering")} -> Vegetative/Tillering
A32: 31 | B32: RSBSA | C32: Agusan del Norte | D32: BUTUAN CITY | E32: ANTONGALON | F32: 1760476 | G32: 46011 | H32: 46114 | I32: ESPORA | J32: SHIRLEY | K32: OTACAN | L32: 0.7696 | M32: 19240 | N32: 3 | O32: 189499 | P32: 16-02-02-009-000021 | Q32: 512612 | S32: 15392 | T32: 3 - P. I. Stg. (REPRODUCTIVE) | U32: 15392 | V32: =(DATE(2026,2,3)-'RICE_Insured Farms_with PPI Pol'!$G32)+IF('RICE_Insured Farms_with PPI Pol'!$H32<>'RICE_Insured Farms_with PPI Pol'!$G32,18,0) -> 63 | W32: {=IFS(V32>120, "Harvested", V32>=113, "Yellow Ripening", V32>=101, "Dough Stage", V32>=93, "Milking Stage", V32>=86, "Flowering", V32>=56, "Panicle Initiation/Booting", V32<56, "Vegetative/Tillering")} -> Panicle Initiation/Booting
A33: 32 | B33: RSBSA | C33: Agusan del Norte | D33: BUTUAN CITY | E33: ANTONGALON | F33: 1760479 | G33: 46011 | H33: 46112 | I33: ESPURA | J33: ROGELIO | K33: GUERTA | L33: 0.7889 | M33: 19722.5 | N33: 3 | O33: 313083 | P33: 16-02-02-009-000020 | Q33: 570069 | S33: 15778 | T33: 3 - P. I. Stg. (REPRODUCTIVE) | U33: 15778 | V33: =(DATE(2026,2,3)-'RICE_Insured Farms_with PPI Pol'!$G33)+IF('RICE_Insured Farms_with PPI Pol'!$H33<>'RICE_Insured Farms_with PPI Pol'!$G33,18,0) -> 63 | W33: {=IFS(V33>120, "Harvested", V33>=113, "Yellow Ripening", V33>=101, "Dough Stage", V33>=93, "Milking Stage", V33>=86, "Flowering", V33>=56, "Panicle Initiation/Booting", V33<56, "Vegetative/Tillering")} -> Panicle Initiation/Booting
A34: 33 | B34: RSBSA | C34: Agusan del Norte | D34: BUTUAN CITY | E34: BASAG | F34: 1761032 | G34: 46034 | H34: 46154 | I34: FERRER | J34: ARNOLD | K34: SALCEDO | L34: 1.9284 | M34: 48210 | N34: 1 | O34: 327460 | P34: 16-02-02-019-000374 | Q34: 707647 | S34: 28926 | T34: 1 - Mn. Tl. Stg. (EARLY VEGETATIVE) | U34: 28926 | V34: =(DATE(2026,2,3)-'RICE_Insured Farms_with PPI Pol'!$G34)+IF('RICE_Insured Farms_with PPI Pol'!$H34<>'RICE_Insured Farms_with PPI Pol'!$G34,18,0) -> 40 | W34: {=IFS(V34>120, "Harvested", V34>=113, "Yellow Ripening", V34>=101, "Dough Stage", V34>=93, "Milking Stage", V34>=86, "Flowering", V34>=56, "Panicle Initiation/Booting", V34<56, "Vegetative/Tillering")} -> Vegetative/Tillering
A35: 34 | B35: RSBSA | C35: Agusan del Norte | D35: BUTUAN CITY | E35: SUMILIHON | F35: 1761001 | G35: 46019 | H35: 46117 | I35: GUIBAO | J35: EDITHA | K35: CAGAS | L35: 0.7237 | M35: 18092.5 | N35: 3 | O35: 175189 | P35: 16-02-02-080-000058 | Q35: 724427 | S35: 14474 | T35: 3 - P. I. Stg. (REPRODUCTIVE) | U35: 14474 | V35: =(DATE(2026,2,3)-'RICE_Insured Farms_with PPI Pol'!$G35)+IF('RICE_Insured Farms_with PPI Pol'!$H35<>'RICE_Insured Farms_with PPI Pol'!$G35,18,0) -> 55 | W35: {=IFS(V35>120, "Harvested", V35>=113, "Yellow Ripening", V35>=101, "Dough Stage", V35>=93, "Milking Stage", V35>=86, "Flowering", V35>=56, "Panicle Initiation/Booting", V35<56, "Vegetative/Tillering")} -> Vegetative/Tillering
A36: 127 | B36: RSBSA | C36: Surigao del Norte | D36: BACUAG | E36: DUGSANGON | F36: 1739640 | G36: 46005 | H36: 46107 | I36: ILIGAN | J36: JERRY | K36: ROGADOR | L36: 0.9395 | M36: 23487.5 | N36: 4 | O36: 135693 | P36: 16-67-02-004-000108 | Q36: 1024467 | S36: 18790 | T36: 4 - Booting Stg. (REPRODUCTIVE) | U36: 18790 | V36: =(DATE(2026,2,3)-'RICE_Insured Farms_with PPI Pol'!$G36)+IF('RICE_Insured Farms_with PPI Pol'!$H36<>'RICE_Insured Farms_with PPI Pol'!$G36,18,0) -> 69 | W36: {=IFS(V36>120, "Harvested", V36>=113, "Yellow Ripening", V36>=101, "Dough Stage", V36>=93, "Milking Stage", V36>=86, "Flowering", V36>=56, "Panicle Initiation/Booting", V36<56, "Vegetative/Tillering")} -> Panicle Initiation/Booting
A37: 129 | B37: RSBSA | C37: Surigao del Norte | D37: BACUAG | E37: DUGSANGON | F37: 1739639 | G37: 46009 | H37: 46111 | I37: INSON | J37: EDWIN | K37: RUBIO | L37: 0.504 | M37: 12600 | N37: 4 | O37: 294640 | P37: 16-67-02-004-000008 | Q37: 1022343 | S37: 10080 | T37: 4 - Booting Stg. (REPRODUCTIVE) | U37: 10080 | V37: =(DATE(2026,2,3)-'RICE_Insured Farms_with PPI Pol'!$G37)+IF('RICE_Insured Farms_with PPI Pol'!$H37<>'RICE_Insured Farms_with PPI Pol'!$G37,18,0) -> 65 | W37: {=IFS(V37>120, "Harvested", V37>=113, "Yellow Ripening", V37>=101, "Dough Stage", V37>=93, "Milking Stage", V37>=86, "Flowering", V37>=56, "Panicle Initiation/Booting", V37<56, "Vegetative/Tillering")} -> Panicle Initiation/Booting
A38: 37 | B38: RSBSA | C38: Agusan del Norte | D38: BUTUAN CITY | E38: AUPAGAN | F38: 1761016 | G38: 46030 | H38: 46125 | I38: GOMO | J38: LOLITA | K38: OMANGUIN | L38: 0.9251 | M38: 23127.5 | N38: 3 | O38: 22963 | P38: 16-02-02-010-000084 | Q38: 722638 | S38: 18502 | T38: 3 - P. I. Stg. (REPRODUCTIVE) | U38: 18502 | V38: =(DATE(2026,2,3)-'RICE_Insured Farms_with PPI Pol'!$G38)+IF('RICE_Insured Farms_with PPI Pol'!$H38<>'RICE_Insured Farms_with PPI Pol'!$G38,18,0) -> 44 | W38: {=IFS(V38>120, "Harvested", V38>=113, "Yellow Ripening", V38>=101, "Dough Stage", V38>=93, "Milking Stage", V38>=86, "Flowering", V38>=56, "Panicle Initiation/Booting", V38<56, "Vegetative/Tillering")} -> Vegetative/Tillering
A39: 38 | B39: RSBSA | C39: Agusan del Norte | D39: BUTUAN CITY | E39: SUMILIHON | F39: 1761001 | G39: 46019 | H39: 46117 | I39: GUIBAO | J39: EDITHA | K39: CAGAS | L39: 0.7237 | M39: 18092.5 | N39: 3 | O39: 175189 | P39: 16-02-02-080-000058 | Q39: 724427 | S39: 14474 | T39: 3 - P. I. Stg. (REPRODUCTIVE) | U39: 14474 | V39: =(DATE(2026,2,3)-'RICE_Insured Farms_with PPI Pol'!$G39)+IF('RICE_Insured Farms_with PPI Pol'!$H39<>'RICE_Insured Farms_with PPI Pol'!$G39,18,0) -> 55 | W39: {=IFS(V39>120, "Harvested", V39>=113, "Yellow Ripening", V39>=101, "Dough Stage", V39>=93, "Milking Stage", V39>=86, "Flowering", V39>=56, "Panicle Initiation/Booting", V39<56, "Vegetative/Tillering")} -> Vegetative/Tillering
A40: 39 | B40: RSBSA | C40: Agusan del Norte | D40: BUTUAN CITY | E40: KINAMLUTAN | F40: 1760498 | G40: 46011 | H40: 46131 | I40: HANTUD | J40: LORLINIE | K40: MAGNO | L40: 1.4952 | M40: 37380 | N40: 2 | O40: 294924 | P40: 16-02-02-049-000136 | Q40: 598084 | S40: 26166 | T40: 2 - Mx. Tl. Stg. (LATE VEGETATIVE) | U40: 26166 | V40: =(DATE(2026,2,3)-'RICE_Insured Farms_with PPI Pol'!$G40)+IF('RICE_Insured Farms_with PPI Pol'!$H40<>'RICE_Insured Farms_with PPI Pol'!$G40,18,0) -> 63 | W40: {=IFS(V40>120, "Harvested", V40>=113, "Yellow Ripening", V40>=101, "Dough Stage", V40>=93, "Milking Stage", V40>=86, "Flowering", V40>=56, "Panicle Initiation/Booting", V40<56, "Vegetative/Tillering")} -> Panicle Initiation/Booting
...

Sheet Additional
A1: No. | B1: Program Type | C1: Province | D1: Municipality | E1: Barangay | F1: Policy No. | G1: Effectivity Date | H1: Expiry Date | I1: Surname | J1: Firstname | K1: Middlename | L1: AreaInsured | M1: AmountofCover | N1: Stage No. | O1: FarmersID | P1: RSBSA No. | Q1: Farm ID | R1: Georef ID | S1: RiskExposureAmount | T1: Stage | U1: EstimatedDamage | V1: Period of Exposure
A2: 11 | B2: RSBSA | C2: Agusan del Norte | D2: BUENAVISTA | E2: MATABAO | F2: 1741165 | G2: 46015 | H2: 46110 | I2: BALANSAG | J2: ANNILEE | K2: CAJELES | L2: 0.4145 | M2: 10362.5 | N2: 4 | O2: 122316 | P2: 16-02-01-011-000178 | Q2: 1085574 | S2: 8290 | T2: 4 - Booting Stg. (REPRODUCTIVE) | U2: 8290 | V2: =VLOOKUP(Additional!$D2, 'Period of Exposures'!B:C, 2, FALSE) -> 33
A3: 12 | B3: RSBSA | C3: Agusan del Norte | D3: BUENAVISTA | E3: TALO-AO | F3: 1741169 | G3: 46015 | H3: 46110 | I3: ZAPANTA | J3: PEDROSA | K3: F. | L3: 0.75 | M3: 18750 | N3: 4 | O3: 515354 | Q3: 1298433 | S3: 15000 | T3: 4 - Booting Stg. (REPRODUCTIVE) | U3: 15000 | V3: =VLOOKUP(Additional!$D3, 'Period of Exposures'!B:C, 2, FALSE) -> 33
A4: 13 | B4: RSBSA | C4: Agusan del Norte | D4: BUTUAN CITY | E4: LEMON | F4: 1760459 | G4: 46016 | H4: 46111 | I4: AYUBAN | J4: PEDRO | K4: CURITAO | L4: 1 | M4: 25000 | N4: 4 | O4: 85805 | P4: 16-02-02-052-000011 | Q4: 193526 | S4: 20000 | T4: 4 - Booting Stg. (REPRODUCTIVE) | U4: 20000 | V4: =VLOOKUP(Additional!$D4, 'Period of Exposures'!B:C, 2, FALSE) -> 33
A5: 14 | B5: RSBSA | C5: Agusan del Norte | D5: BUTUAN CITY | E5: TINIWISAN | F5: 1760463 | G5: 46016 | H5: 46111 | I5: BAYRON | J5: AMELITA | K5: M. | L5: 0.9345 | M5: 23362.5 | N5: 4 | O5: 1803 | P5: 16-02-02-086-000057 | Q5: 696356 | S5: 18690 | T5: 4 - Booting Stg. (REPRODUCTIVE) | U5: 18690 | V5: =VLOOKUP(Additional!$D5, 'Period of Exposures'!B:C, 2, FALSE) -> 33
A6: 15 | B6: RSBSA | C6: Agusan del Norte | D6: BUTUAN CITY | E6: ANTONGALON | F6: 1760479 | G6: 46007 | H6: 46109 | I6: CABONCE | J6: EDUARDO JR. | K6: POBLETE | L6: 1.76 | M6: 44000 | N6: 4 | O6: 226842 | Q6: 602937 | S6: 35200 | T6: 4 - Booting Stg. (REPRODUCTIVE) | U6: 35200 | V6: =VLOOKUP(Additional!$D6, 'Period of Exposures'!B:C, 2, FALSE) -> 33
A7: 16 | B7: RSBSA | C7: Agusan del Norte | D7: BUTUAN CITY | E7: TALIGAMAN | F7: 1760476 | G7: 46011 | H7: 46102 | I7: DELA CRUZ | J7: CELERINA | K7: A | L7: 0.7502 | M7: 18755 | N7: 4 | O7: 324686 | Q7: 604277 | S7: 15004 | T7: 4 - Booting Stg. (REPRODUCTIVE) | U7: 15004 | V7: =VLOOKUP(Additional!$D7, 'Period of Exposures'!B:C, 2, FALSE) -> 33
A8: 17 | B8: RSBSA | C8: Agusan del Norte | D8: BUTUAN CITY | E8: ANTONGALON | F8: 1760479 | G8: 46007 | H8: 46109 | I8: GALENDEZ | J8: WALTER | K8: ALPAR | L8: 0.8 | M8: 20000 | N8: 4 | O8: 16093 | P8: 16-02-02-009-000024 | Q8: 603981 | S8: 16000 | T8: 4 - Booting Stg. (REPRODUCTIVE) | U8: 16000 | V8: =VLOOKUP(Additional!$D8, 'Period of Exposures'!B:C, 2, FALSE) -> 33
A9: 18 | B9: RSBSA | C9: Agusan del Norte | D9: BUTUAN CITY | E9: BASAG | F9: 1760483 | G9: 46011 | H9: 46106 | I9: GARDOCE | J9: MARY ANN | K9: PALER | L9: 0.8 | M9: 20000 | N9: 4 | O9: 362061 | P9: 16-02-02-019-000142 | Q9: 708053 | S9: 16000 | T9: 4 - Booting Stg. (REPRODUCTIVE) | U9: 16000 | V9: =VLOOKUP(Additional!$D9, 'Period of Exposures'!B:C, 2, FALSE) -> 33
A10: 19 | B10: RSBSA | C10: Agusan del Norte | D10: BUTUAN CITY | E10: ANTONGALON | F10: 1760482 | G10: 46011 | H10: 46106 | I10: HINGPIT | J10: BEBIANA | K10: NAVARRO | L10: 0.828 | M10: 20700 | N10: 4 | O10: 16086 | P10: 16-02-02-009-000060 | Q10: 603991 | S10: 16560 | T10: 4 - Booting Stg. (REPRODUCTIVE) | U10: 16560 | V10: =VLOOKUP(Additional!$D10, 'Period of Exposures'!B:C, 2, FALSE) -> 33
A11: 20 | B11: RSBSA | C11: Agusan del Norte | D11: BUTUAN CITY | E11: ANTONGALON | F11: 1760482 | G11: 46011 | H11: 46106 | I11: MAG-ISA | J11: ANICETO | K11: MALGAPO | L11: 1.8465 | M11: 46162.5 | N11: 4 | O11: 192451 | Q11: 556963 | S11: 36930 | T11: 4 - Booting Stg. (REPRODUCTIVE) | U11: 36930 | V11: =VLOOKUP(Additional!$D11, 'Period of Exposures'!B:C, 2, FALSE) -> 33
A12: 21 | B12: RSBSA | C12: Agusan del Norte | D12: BUTUAN CITY | E12: ANTONGALON | F12: 1760482 | G12: 46011 | H12: 46106 | I12: TAGALOG | J12: REY | K12: MOSQUEDA | L12: 1.12 | M12: 28000 | N12: 4 | O12: 294848 | P12: 16-02-02-009-000042 | Q12: 604291 | S12: 22400 | T12: 4 - Booting Stg. (REPRODUCTIVE) | U12: 22400 | V12: =VLOOKUP(Additional!$D12, 'Period of Exposures'!B:C, 2, FALSE) -> 33
A13: 22 | B13: RSBSA | C13: Agusan del Norte | D13: BUTUAN CITY | E13: SANTO NIï¿½O | F13: 1760496 | G13: 46013 | H13: 46108 | I13: DE JESUS | J13: ERWIN | K13: MATIAS | L13: 0.8532 | M13: 21330 | N13: 4 | O13: 296062 | P13: 16-02-02-100-000177 | Q13: 875837 | S13: 17064 | T13: 4 - Booting Stg. (REPRODUCTIVE) | U13: 17064 | V13: =VLOOKUP(Additional!$D13, 'Period of Exposures'!B:C, 2, FALSE) -> 33
A14: 23 | B14: RSBSA | C14: Agusan del Norte | D14: BUTUAN CITY | E14: SANTO NIï¿½O | F14: 1760495 | G14: 46010 | H14: 46105 | I14: DEJADO | J14: SARAH JANE | K14: DAGOOC | L14: 1.0879 | M14: 27197.5 | N14: 4 | O14: 175178 | P14: 16-02-02-100-000485 | Q14: 874926 | S14: 21758 | T14: 4 - Booting Stg. (REPRODUCTIVE) | U14: 21758 | V14: =VLOOKUP(Additional!$D14, 'Period of Exposures'!B:C, 2, FALSE) -> 33
A15: 24 | B15: RSBSA | C15: Agusan del Norte | D15: BUTUAN CITY | E15: LOS ANGELES | F15: 1760486 | G15: 46015 | H15: 46111 | I15: ABOYME | J15: RODOLFO | K15: ALIMA | L15: 1.4924 | M15: 37310 | N15: 4 | O15: 109575 | Q15: 606105 | S15: 29848 | T15: 4 - Booting Stg. (REPRODUCTIVE) | U15: 29848 | V15: =VLOOKUP(Additional!$D15, 'Period of Exposures'!B:C, 2, FALSE) -> 33
A16: 25 | B16: RSBSA | C16: Agusan del Norte | D16: BUTUAN CITY | E16: TAGABACA | F16: 1760497 | G16: 46016 | H16: 46111 | I16: CALO | J16: EVA | K16: LERIA | L16: 0.3833 | M16: 9582.5 | N16: 4 | O16: 182255 | P16: 16-02-02-082-000117 | Q16: 548181 | S16: 7666 | T16: 4 - Booting Stg. (REPRODUCTIVE) | U16: 7666 | V16: =VLOOKUP(Additional!$D16, 'Period of Exposures'!B:C, 2, FALSE) -> 33
A17: 26 | B17: RSBSA | C17: Agusan del Norte | D17: BUTUAN CITY | E17: LOS ANGELES | F17: 1760486 | G17: 46014 | H17: 46109 | I17: GAGULA | J17: DIOSDADA | K17: MENDAï¿½A | L17: 2 | M17: 50000 | N17: 4 | O17: 159083 | Q17: 696421 | S17: 40000 | T17: 4 - Booting Stg. (REPRODUCTIVE) | U17: 40000 | V17: =VLOOKUP(Additional!$D17, 'Period of Exposures'!B:C, 2, FALSE) -> 33
A18: 27 | B18: RSBSA | C18: Agusan del Norte | D18: BUTUAN CITY | E18: TAGABACA | F18: 1760497 | G18: 46014 | H18: 46110 | I18: GERONA | J18: MARIO | K18: MARAVILLA | L18: 1.2494 | M18: 31235 | N18: 4 | O18: 98353 | P18: 16-02-02-082-000133 | Q18: 602926 | S18: 24988 | T18: 4 - Booting Stg. (REPRODUCTIVE) | U18: 24988 | V18: =VLOOKUP(Additional!$D18, 'Period of Exposures'!B:C, 2, FALSE) -> 33
A19: 28 | B19: OTHER - LI LC | C19: Agusan del Norte | D19: BUTUAN CITY | E19: LOS ANGELES | F19: 1760852 | G19: 46014 | H19: 46109 | I19: LABASTIDA | J19: EDWIN | K19: N | L19: 1.2175 | M19: 60000 | N19: 4 | O19: 1282 | P19: 16-02-02-056-000303 | Q19: 717030 | S19: 48000 | T19: 4 - Booting Stg. (REPRODUCTIVE) | U19: 48000 | V19: =VLOOKUP(Additional!$D19, 'Period of Exposures'!B:C, 2, FALSE) -> 33
A20: 29 | B20: RSBSA | C20: Agusan del Norte | D20: BUTUAN CITY | E20: TAGABACA | F20: 1760497 | G20: 46015 | H20: 46110 | I20: PINEDA | J20: GELIA | K20: LAYOG | L20: 0.6575 | M20: 16437.5 | N20: 4 | O20: 111328 | Q20: 689094 | S20: 13150 | T20: 4 - Booting Stg. (REPRODUCTIVE) | U20: 13150 | V20: =VLOOKUP(Additional!$D20, 'Period of Exposures'!B:C, 2, FALSE) -> 33
A21: 30 | B21: RSBSA | C21: Agusan del Norte | D21: BUTUAN CITY | E21: TAGABACA | F21: 1760497 | G21: 46014 | H21: 46109 | I21: PINEDA | J21: RETCHEL | K21: LAYOG | L21: 1.0825 | M21: 27062.5 | N21: 4 | O21: 354521 | Q21: 688314 | S21: 21650 | T21: 4 - Booting Stg. (REPRODUCTIVE) | U21: 21650 | V21: =VLOOKUP(Additional!$D21, 'Period of Exposures'!B:C, 2, FALSE) -> 33
A22: 31 | B22: RSBSA | C22: Agusan del Norte | D22: BUTUAN CITY | E22: MANDAMO | F22: 1761010 | G22: 46017 | H22: 46104 | I22: ABLIN | J22: DARIO | K22: ANDIG | L22: 0.1808 | M22: 4520 | N22: 4 | O22: 419037 | P22: 16-02-02-064-000219 | Q22: 1330925 | S22: 3616 | T22: 4 - Booting Stg. (REPRODUCTIVE) | U22: 3616 | V22: =VLOOKUP(Additional!$D22, 'Period of Exposures'!B:C, 2, FALSE) -> 33
A23: 32 | B23: ANYO PROGRAM | C23: Agusan del Norte | D23: BUTUAN CITY | E23: SANTO NIï¿½O | F23: 1760484 | G23: 46009 | H23: 46104 | I23: ABUCAY | J23: ROBENSON | K23: SUPAS | L23: 2 | M23: 80000 | N23: 4 | O23: 199112 | P23: 16-02-02-100-000248 | Q23: 1318899 | S23: 64000 | T23: 4 - Booting Stg. (REPRODUCTIVE) | U23: 64000 | V23: =VLOOKUP(Additional!$D23, 'Period of Exposures'!B:C, 2, FALSE) -> 33
A24: 33 | B24: RSBSA | C24: Agusan del Norte | D24: BUTUAN CITY | E24: MANDAMO | F24: 1760491 | G24: 46013 | H24: 46109 | I24: ANINAO | J24: CHET | K24: ARISTAN | L24: 0.8537 | M24: 21342.5 | N24: 4 | O24: 496667 | Q24: 1232068 | S24: 17074 | T24: 4 - Booting Stg. (REPRODUCTIVE) | U24: 17074 | V24: =VLOOKUP(Additional!$D24, 'Period of Exposures'!B:C, 2, FALSE) -> 33
A25: 34 | B25: RSBSA | C25: Agusan del Norte | D25: BUTUAN CITY | E25: MANDAMO | F25: 1760491 | G25: 46013 | H25: 46109 | I25: BAGOLANTOY | J25: CRISTOPHER | K25: CAGAS | L25: 0.3783 | M25: 9457.5 | N25: 4 | O25: 325595 | P25: 16-02-02-064-000027 | Q25: 1232069 | S25: 7566 | T25: 4 - Booting Stg. (REPRODUCTIVE) | U25: 7566 | V25: =VLOOKUP(Additional!$D25, 'Period of Exposures'!B:C, 2, FALSE) -> 33
A26: 35 | B26: ANYO PROGRAM | C26: Agusan del Norte | D26: BUTUAN CITY | E26: BANZA | F26: 1760484 | G26: 46007 | H26: 46102 | I26: BALDO | J26: CHRISTIAN MARK | K26: GONZALES | L26: 2.6669 | M26: 120000 | N26: 4 | O26: 170895 | P26: 16-02-02-017-000107 | Q26: 1199086 | S26: 96000 | T26: 4 - Booting Stg. (REPRODUCTIVE) | U26: 96000 | V26: =VLOOKUP(Additional!$D26, 'Period of Exposures'!B:C, 2, FALSE) -> 33
A27: 36 | B27: RSBSA | C27: Agusan del Norte | D27: BUTUAN CITY | E27: MANDAMO | F27: 1761008 | G27: 46017 | H27: 46109 | I27: BASLOTE | J27: LEONORA | K27: JUMANOY | L27: 0.6385 | M27: 15962.5 | N27: 4 | O27: 131767 | P27: 16-02-02-064-000168 | Q27: 1330247 | S27: 12770 | T27: 4 - Booting Stg. (REPRODUCTIVE) | U27: 12770 | V27: =VLOOKUP(Additional!$D27, 'Period of Exposures'!B:C, 2, FALSE) -> 33
A28: 37 | B28: RSBSA | C28: Agusan del Norte | D28: BUTUAN CITY | E28: MANDAMO | F28: 1760491 | G28: 46012 | H28: 46110 | I28: BOHOLANO | J28: FRANCISCO | K28: O. | L28: 0.5893 | M28: 14732.5 | N28: 4 | O28: 441219 | P28: 16-02-02-064-000222 | Q28: 1149544 | S28: 11786 | T28: 4 - Booting Stg. (REPRODUCTIVE) | U28: 11786 | V28: =VLOOKUP(Additional!$D28, 'Period of Exposures'!B:C, 2, FALSE) -> 33
A29: 38 | B29: RSBSA | C29: Agusan del Norte | D29: BUTUAN CITY | E29: MANDAMO | F29: 1760492 | G29: 46014 | H29: 46109 | I29: BOHOLANO | J29: JOSEPHINE | K29: MUSICO | L29: 0.3 | M29: 7500 | N29: 4 | O29: 103007 | P29: 16-02-02-064-000065 | Q29: 1276853 | S29: 6000 | T29: 4 - Booting Stg. (REPRODUCTIVE) | U29: 6000 | V29: =VLOOKUP(Additional!$D29, 'Period of Exposures'!B:C, 2, FALSE) -> 33
A30: 39 | B30: RSBSA | C30: Agusan del Norte | D30: BUTUAN CITY | E30: ANTONGALON | F30: 1760476 | G30: 46011 | H30: 46104 | I30: BRIONES | J30: RODANTE | K30: MAG-ISA | L30: 0.4313 | M30: 10782.5 | N30: 4 | O30: 496305 | P30: 16-02-02-009-000171 | Q30: 1276977 | S30: 8626 | T30: 4 - Booting Stg. (REPRODUCTIVE) | U30: 8626 | V30: =VLOOKUP(Additional!$D30, 'Period of Exposures'!B:C, 2, FALSE) -> 33
A31: 40 | B31: RSBSA | C31: Agusan del Norte | D31: BUTUAN CITY | E31: MAGUINDA | F31: 1760463 | G31: 46008 | H31: 46103 | I31: CANAMA | J31: RIZALINA | K31: PORES | L31: 2 | M31: 50000 | N31: 4 | O31: 87173 | P31: 16-02-02-060-000274 | Q31: 1133199 | S31: 40000 | T31: 4 - Booting Stg. (REPRODUCTIVE) | U31: 40000 | V31: =VLOOKUP(Additional!$D31, 'Period of Exposures'!B:C, 2, FALSE) -> 33
A32: 41 | B32: RSBSA | C32: Agusan del Norte | D32: BUTUAN CITY | E32: LOS ANGELES | F32: 1760465 | G32: 46016 | H32: 46111 | I32: CARILLO | J32: DOMINADOR | K32: SAYSON | L32: 2 | M32: 50000 | N32: 4 | O32: 196783 | P32: 16-02-02-056-000393 | Q32: 1273079 | S32: 40000 | T32: 4 - Booting Stg. (REPRODUCTIVE) | U32: 40000 | V32: =VLOOKUP(Additional!$D32, 'Period of Exposures'!B:C, 2, FALSE) -> 33
A33: 42 | B33: RSBSA | C33: Agusan del Norte | D33: BUTUAN CITY | E33: ANTONGALON | F33: 1760476 | G33: 46017 | H33: 46107 | I33: CARIN | J33: EDITHA | K33: ROCA | L33: 0.4305 | M33: 10762.5 | N33: 4 | O33: 236229 | Q33: 1272717 | S33: 8610 | T33: 4 - Booting Stg. (REPRODUCTIVE) | U33: 8610 | V33: =VLOOKUP(Additional!$D33, 'Period of Exposures'!B:C, 2, FALSE) -> 33
A34: 43 | B34: RSBSA | C34: Agusan del Norte | D34: BUTUAN CITY | E34: MANDAMO | F34: 1761010 | G34: 46021 | H34: 46107 | I34: CASSION | J34: JOSEPH | K34: SILAGAN | L34: 0.9957 | M34: 24892.5 | N34: 4 | O34: 473231 | P34: 16-02-02-064-000282 | Q34: 1113738 | S34: 19914 | T34: 4 - Booting Stg. (REPRODUCTIVE) | U34: 19914 | V34: =VLOOKUP(Additional!$D34, 'Period of Exposures'!B:C, 2, FALSE) -> 33
A35: 44 | B35: RSBSA | C35: Agusan del Norte | D35: BUTUAN CITY | E35: MANDAMO | F35: 1761004 | G35: 46014 | H35: 46109 | I35: CATALUNA | J35: JESMAR | K35: B | L35: 0.4453 | M35: 11132.5 | N35: 4 | O35: 441221 | Q35: 1276804 | S35: 8906 | T35: 4 - Booting Stg. (REPRODUCTIVE) | U35: 8906 | V35: =VLOOKUP(Additional!$D35, 'Period of Exposures'!B:C, 2, FALSE) -> 33
A36: 45 | B36: RSBSA | C36: Agusan del Norte | D36: BUTUAN CITY | E36: MANDAMO | F36: 1760491 | G36: 46013 | H36: 46111 | I36: CATALUï¿½A | J36: ELENA | K36: RACHO | L36: 0.5018 | M36: 12545 | N36: 4 | O36: 315183 | P36: 16-02-02-064-000062 | Q36: 962621 | S36: 10036 | T36: 4 - Booting Stg. (REPRODUCTIVE) | U36: 10036 | V36: =VLOOKUP(Additional!$D36, 'Period of Exposures'!B:C, 2, FALSE) -> 33
A37: 46 | B37: RSBSA | C37: Agusan del Norte | D37: BUTUAN CITY | E37: MANDAMO | F37: 1760491 | G37: 46014 | H37: 46111 | I37: CATALUï¿½A | J37: SERGIO | K37: CABAï¿½AS | L37: 0.287 | M37: 7175 | N37: 4 | O37: 391963 | P37: 16-02-02-064-000105 | Q37: 1113886 | S37: 5740 | T37: 4 - Booting Stg. (REPRODUCTIVE) | U37: 5740 | V37: =VLOOKUP(Additional!$D37, 'Period of Exposures'!B:C, 2, FALSE) -> 33
A38: 47 | B38: RSBSA | C38: Agusan del Norte | D38: BUTUAN CITY | E38: MANDAMO | F38: 1760491 | G38: 46013 | H38: 46111 | I38: CATALUï¿½A | J38: THALIA | L38: 0.4335 | M38: 10837.5 | N38: 4 | O38: 435870 | P38: 16-02-02-064-000218 | Q38: 1149514 | S38: 8670 | T38: 4 - Booting Stg. (REPRODUCTIVE) | U38: 8670 | V38: =VLOOKUP(Additional!$D38, 'Period of Exposures'!B:C, 2, FALSE) -> 33
A39: 48 | B39: RSBSA | C39: Agusan del Norte | D39: BUTUAN CITY | E39: MAGUINDA | F39: 1760463 | G39: 46016 | H39: 46111 | I39: CHEQUITO | J39: DEVELYN | K39: CHU | L39: 2 | M39: 50000 | N39: 4 | O39: 334509 | P39: 16-02-02-060-000333 | Q39: 1277293 | S39: 40000 | T39: 4 - Booting Stg. (REPRODUCTIVE) | U39: 40000 | V39: =VLOOKUP(Additional!$D39, 'Period of Exposures'!B:C, 2, FALSE) -> 33
A40: 49 | B40: RSBSA | C40: Agusan del Norte | D40: BUTUAN CITY | E40: MAGUINDA | F40: 1760463 | G40: 46012 | H40: 46107 | I40: CHEQUITO | J40: PEDRO | K40: BASNIG | L40: 2 | M40: 50000 | N40: 4 | O40: 95291 | P40: 16-02-02-060-000205 | Q40: 1319215 | S40: 40000 | T40: 4 - Booting Stg. (REPRODUCTIVE) | U40: 40000 | V40: =VLOOKUP(Additional!$D40, 'Period of Exposures'!B:C, 2, FALSE) -> 33
...

Sheet Qualified for ParamIns. 
A1: TWS NO. | B1: 2 | C1: Typhoon Basyang
A2: Period of Exposure | B2: 33 HRS | C2: 02/05/2026 1:00:00 am to 02/06/2026 10:00:00 am
A3: Wind Velocity | B3: 62-88kph | C3: TY Data Source: PAG-ASA
C4: Insurance Record: RISK EXPOSURE as of 02/09/2026
A5: No. | B5: Program Type | C5: Province | D5: Municipality | E5: Barangay | F5: Policy No. | G5: Effectivity Date | H5: Expiry Date | I5: Surname | J5: Firstname | K5: Middlename | L5: AreaInsured | M5: AmountofCover | N5: Stage No. | O5: FarmersID | P5: RSBSA No. | Q5: Farm ID | R5: Georef ID | S5: RiskExposureAmount | T5: Stage | U5: EstimatedDamage | V5: Period of Exposure, hrs
A6: 1 | B6: RSBSA | C6: Agusan del Norte | D6: BUTUAN CITY | E6: BAOBAOAN | F6: 1760452 | G6: 46001 | H6: 46101 | I6: LADRA | J6: ANASTACIA | K6: TULIAO | L6: 0.76 | M6: 19000 | N6: 5 | O6: 233204 | P6: 16-02-02-018-000140 | Q6: 613381 | S6: 17100 | T6: 5 - Flowering Stg. (LATE REPRODUCTIVE) | U6: 17100 | V6: 33
A7: 2 | B7: RSBSA | C7: Agusan del Norte | D7: BUTUAN CITY | E7: LOS ANGELES | F7: 1760465 | G7: 46006 | H7: 46101 | I7: ALTOVEROS | J7: VERONICA | K7: DOLOROC | L7: 2 | M7: 50000 | N7: 5 | O7: 418006 | P7: 16-02-02-056-000248 | Q7: 1027840 | S7: 45000 | T7: 5 - Flowering Stg. (LATE REPRODUCTIVE) | U7: 45000 | V7: 33
A8: 3 | B8: RSBSA | C8: Agusan del Norte | D8: BUTUAN CITY | E8: MAGUINDA | F8: 1760463 | G8: 46006 | H8: 46101 | I8: BAHALLA | J8: CRISTINA | K8: PORES | L8: 2 | M8: 50000 | N8: 5 | O8: 87172 | P8: 16-02-02-060-000223 | Q8: 1034013 | S8: 45000 | T8: 5 - Flowering Stg. (LATE REPRODUCTIVE) | U8: 45000 | V8: 33
A9: 4 | B9: ANYO PROGRAM | C9: Agusan del Norte | D9: BUTUAN CITY | E9: SANTO NIï¿½O | F9: 1760484 | G9: 46001 | H9: 46096 | I9: BATUCAN | J9: VIRGIE | K9: RESTAURO | L9: 1.8476 | M9: 80000 | N9: 5 | O9: 16816 | P9: 16-02-02-100-000278 | Q9: 1044382 | S9: 72000 | T9: 5 - Flowering Stg. (LATE REPRODUCTIVE) | U9: 72000 | V9: 33
A10: 5 | B10: RSBSA | C10: Agusan del Norte | D10: BUTUAN CITY | E10: BIT-OS | F10: 1760487 | G10: 46003 | H10: 46101 | I10: CORRALES | J10: DOMINADOR JR. | K10: B. | L10: 1.1418 | M10: 28545 | N10: 5 | O10: 425376 | Q10: 1228634 | S10: 25690.5 | T10: 5 - Flowering Stg. (LATE REPRODUCTIVE) | U10: 25690.5 | V10: 33
A11: 6 | B11: RSBSA | C11: Agusan del Norte | D11: BUTUAN CITY | E11: BIT-OS | F11: 1760481 | G11: 46001 | H11: 46096 | I11: LAMBAN | J11: TITO | K11: SARANIANA | L11: 0.8509 | M11: 21272.5 | N11: 5 | O11: 177090 | P11: 16-02-02-022-000030 | Q11: 1326017 | S11: 19145.25 | T11: 5 - Flowering Stg. (LATE REPRODUCTIVE) | U11: 19145.25 | V11: 33
A12: 7 | B12: RSBSA | C12: Agusan del Norte | D12: BUTUAN CITY | E12: LOS ANGELES | F12: 1760465 | G12: 45996 | H12: 46093 | I12: MALUPA | J12: DELIA | K12: A. | L12: 1.44 | M12: 36000 | N12: 5 | O12: 327443 | P12: 16-02-02-056-000357 | Q12: 1318631 | S12: 32400 | T12: 5 - Flowering Stg. (LATE REPRODUCTIVE) | U12: 32400 | V12: 33
A13: 8 | B13: RSBSA | C13: Agusan del Norte | D13: BUTUAN CITY | E13: MANDAMO | F13: 1761008 | G13: 46019 | H13: 46097 | I13: PEï¿½ALOGA | J13: VILMAR | K13: REBEL | L13: 0.9258 | M13: 23145 | N13: 5 | O13: 325507 | P13: 16-02-02-064-000097 | Q13: 1329904 | S13: 20830.5 | T13: 5 - Flowering Stg. (LATE REPRODUCTIVE) | U13: 20830.5 | V13: 33
A14: 9 | B14: RSBSA | C14: Agusan del Norte | D14: BUTUAN CITY | E14: MAGUINDA | F14: 1760463 | G14: 46006 | H14: 46101 | I14: SAGRAGAO | J14: LEONOR | K14: PORES | L14: 2 | M14: 50000 | N14: 5 | O14: 334404 | P14: 16-02-02-060-000059 | Q14: 716349 | S14: 45000 | T14: 5 - Flowering Stg. (LATE REPRODUCTIVE) | U14: 45000 | V14: 33
A15: 10 | B15: AGRI-AGRA - OTHERS | C15: Agusan del Norte | D15: BUTUAN CITY | E15: MAGUINDA | F15: 1760471 | G15: 46003 | H15: 46098 | I15: SARSALE | J15: ALEXES | K15: CONCEPCION | L15: 0.5015 | M15: 10030 | N15: 5 | O15: 476841 | P15: 16-02-02-060-000362 | Q15: 1324332 | S15: 9027 | T15: 5 - Flowering Stg. (LATE REPRODUCTIVE) | U15: 9027 | V15: 33
A16: 11 | B16: AGRI-AGRA - OTHERS | C16: Agusan del Norte | D16: BUTUAN CITY | E16: MAGUINDA | F16: 1760471 | G16: 46003 | H16: 46098 | I16: SARSALE | J16: DISELDA | K16: C. | L16: 0.5564 | M16: 11128 | N16: 5 | O16: 325322 | P16: 16-02-02-060-000186 | Q16: 1275867 | S16: 10015.2 | T16: 5 - Flowering Stg. (LATE REPRODUCTIVE) | U16: 10015.2 | V16: 33
A17: 12 | B17: RSBSA | C17: Agusan del Norte | D17: BUTUAN CITY | E17: MANDAMO | F17: 1761004 | G17: 46011 | H17: 46096 | I17: SILAGAN | J17: JOSELITO JR. | K17: MANTILLA | L17: 0.2553 | M17: 6382.5 | N17: 5 | O17: 332033 | Q17: 1149493 | S17: 5744.25 | T17: 5 - Flowering Stg. (LATE REPRODUCTIVE) | U17: 5744.25 | V17: 33
A18: 13 | B18: RSBSA | C18: Agusan del Norte | D18: BUTUAN CITY | E18: MANDAMO | F18: 1761010 | G18: 46018 | H18: 46091 | I18: SILAGAN | J18: RAFAEL | K18: MUSICO | L18: 0.9157 | M18: 22892.5 | N18: 6 | O18: 325519 | P18: 16-02-02-064-000078 | Q18: 1328740 | S18: 20603.25 | T18: 6 - Milking Stg. (LATE REPRODUCTIVE) | U18: 20603.25 | V18: 33
A19: 14 | B19: RSBSA | C19: Agusan del Norte | D19: BUTUAN CITY | E19: LOS ANGELES | F19: 1760467 | G19: 46004 | H19: 46100 | I19: SUPAS | J19: JUNITO | K19: POLONGASA | L19: 1.4685 | M19: 36712.5 | N19: 5 | O19: 389570 | P19: 16-02-02-056-000183 | Q19: 1132749 | S19: 33041.25 | T19: 5 - Flowering Stg. (LATE REPRODUCTIVE) | U19: 33041.25 | V19: 33
A20: 15 | B20: RSBSA | C20: Agusan del Norte | D20: BUTUAN CITY | E20: BANZA | F20: 1760488 | G20: 46002 | H20: 46101 | I20: TINGCOY | J20: ARIEL | K20: AZOTE | L20: 1 | M20: 25000 | N20: 5 | O20: 291992 | P20: 16-02-02-017-000099 | Q20: 1265245 | S20: 22500 | T20: 5 - Flowering Stg. (LATE REPRODUCTIVE) | U20: 22500 | V20: 33
A21: 16 | B21: RSBSA | C21: Agusan del Norte | D21: BUTUAN CITY | E21: BIT-OS | F21: 1760481 | G21: 46002 | H21: 46097 | I21: VILLARO | J21: RENATO | K21: BAMBE | L21: 1 | M21: 25000 | N21: 5 | O21: 278710 | P21: 16-02-02-022-000043 | Q21: 1228633 | S21: 22500 | T21: 5 - Flowering Stg. (LATE REPRODUCTIVE) | U21: 22500 | V21: 33
A22: 17 | B22: RSBSA | C22: Agusan del Norte | D22: CABADBARAN CITY | E22: LA UNION | F22: 1761011 | G22: 46006 | H22: 46101 | I22: MONDIGO | J22: LILIBETH | K22: CALUNDRE | L22: 0.5058 | M22: 12645 | N22: 5 | O22: 22201 | P22: 16-02-03-018-000091 | Q22: 949199 | S22: 11380.5 | T22: 5 - Flowering Stg. (LATE REPRODUCTIVE) | U22: 11380.5 | V22: 33

Sheet Period of Exposures
A1: Province | B1: Municipality | C1: Duration (Hours) | D1: TCWS Level | E1: Start Time | F1: End Time
A2: Agusan del Norte | B2: Buenavista | C2: 33 | D2: TCWS No. 2 | E2: 46058.042 | F2: 46059.417
A3: Agusan del Norte | B3: Butuan City | C3: 33 | D3: TCWS No. 2 | E3: 46058.042 | F3: 46059.417
A4: Agusan del Norte | B4: Cabadbaran City | C4: 33 | D4: TCWS No. 2 | E4: 46058.042 | F4: 46059.417
A5: Agusan del Norte | B5: Carmen | C5: 33 | D5: TCWS No. 2 | E5: 46058.042 | F5: 46059.417
A6: Agusan del Norte | B6: Jabonga | C6: 33 | D6: TCWS No. 2 | E6: 46058.042 | F6: 46059.417
A7: Agusan del Norte | B7: Kitcharao | C7: 33 | D7: TCWS No. 2 | E7: 46058.042 | F7: 46059.417
A8: Agusan del Norte | B8: Las Nieves | C8: 33 | D8: TCWS No. 2 | E8: 46058.042 | F8: 46059.417
A9: Agusan del Norte | B9: Magallanes | C9: 33 | D9: TCWS No. 2 | E9: 46058.042 | F9: 46059.417
A10: Agusan del Norte | B10: Nasipit | C10: 33 | D10: TCWS No. 2 | E10: 46058.042 | F10: 46059.417
A11: Agusan del Norte | B11: Remedios T. Romualdez | C11: 33 | D11: TCWS No. 2 | E11: 46058.042 | F11: 46059.417
A12: Agusan del Norte | B12: Santiago | C12: 33 | D12: TCWS No. 2 | E12: 46058.042 | F12: 46059.417
A13: Agusan del Norte | B13: Tubay | C13: 33 | D13: TCWS No. 2 | E13: 46058.042 | F13: 46059.417
... A113: Surigao del Sur | B113: Tago | C113: 36 | D113: TCWS No. 2 | E113: 46057.917 | F113: 46059.417
